Workbook

Sheet 1. Manager Page
B2: Name of Stochastic Inputs | C2: Desription | D2: Any Assumptions and Justifications | E2: Values
B3: Daily Online Reservations | C3: Number of online room booking requests received for the selected room type during one peak-season day. | D3: Reservation demand is assumed to respond to Room Price. During the June-August peak snow season, reservation demand is expected to exceed physical room capacity, making overbooking management significant. | E3: Normal Distribution Mean = 570 ($499) / 510 ($599) SD = 48 / 46
B4: Walk-in Guests | C4: Number of guests arriving without prior booking on the same day. | D4: Walk-in demand varies daily. Walk-in guests are accepted only when the resort remains within its booking and overbooking policy. | E4: Poisson Distribution (λ = 40)
B5: Late Cancellations | C5: Number of accepted bookings cancelled shortly before arrival. | D5: Cancellation probability is assumed to decrease as Late Cancellation Fee increases. | E5: Binomial Distribution Cancellation probability = 8% ($100 fee) / 5% ($150 fee)
B6: Daily Miscellaneous Expenses | C6: Additional daily operating expenses not captured by fixed staffing or housekeeping costs. | D6: Some operating expenses vary daily due to maintenance needs, guest service requirements, supplies, and seasonal workload fluctuations. | E6: Uniform Distribution Lower Limit = $2,000 Upper Limit = $5,000
B8: Decision Variables
B9: Room Price | C9: Daily room rate charged for the selected room type. | D9: Room Price is the primary managerial decision because it directly affects demand, revenue, occupancy performance, and daily profit. Assume the room type are middle-range one-bedroom, price range referenced to real price range for this room type in Mt Hotham Alpine Resort | E9: $499 / $599
B10: Late Cancellation Fee | C10: Fee charged to customers who cancel close to arrival. | D10: The cancellation fee is included as a controllable policy decision because it may reduce revenue loss from late cancellations and influence cancellation behaviour. | E10: $100 / $150
B12: Fixed Inputs
B13: Room Capacity | C13: Total number of rooms available for the selected room type. | D13: Accommodation capacity remains fixed because the resort has a limited number of physical rooms available. | E13: 450 rooms
B14: Overbooking Rate | C14: Percentage of additional bookings accepted above room capacity. | D14: The resort applies a controlled overbooking policy to reduce the impact of cancellations and unused rooms while maintaining operational control over guest displacement risk. | E14: 7% (Similar range to late cancellation rate)
B15: Housekeeping Cost per Room | C15: Cleaning and servicing cost for each occupied room. | D15: Housekeeping cost increases with occupied rooms because each occupied room requires cleaning, linen service, and room preparation. | E15: $100 per room
B16: Compensation Cost Rule | C16: Compensation paid to guests affected by overbooking. | D16: Guests displaced due to overbooking are compensated with an amount equivalent to one night’s accommodation charge. | E16: 100% of one room price
B17: Daily Fixed Operating Cost | C17: Fixed daily cost such as staffing, utilities, administration, and facility operations. | D17: Certain operating costs are incurred regardless of occupancy level, including staffing commitments, utilities, administration, and core facility operations. | E17: 20000
B19: Intermediate Variables
B20: Available Booking Rooms | C20: Number of rooms available for bookings | D20: Equals to total capacity plus the overbooking rate | E20: Calculated
B21: Accepted Online Reservations | C21: Number of online reservations accepted after applying room capacity and overbooking policy. | D21: Accepted reservations are constrained so that the resort does not accept unlimited demand beyond its operational booking policy. | E21: Calculated
B22: Available Walk-ins Rooms | C22: Remaining booking spaces after accepted online reservations. | D22: Determines whether additional walk-in guests can be accepted while remaining within the overbooking policy. | E22: Calculated
B23: Accepted Walk-in Guests | C23: Number of walk-in guests accepted within remaining booking spaces. | D23: Walk-in guests are accepted only when booking space remains available under the overbooking policy. | E23: Calculated
B24: Total Accepted Bookings | C24: Accepted online reservations plus accepted walk-in guests. | D24: Represents total customers accepted by the resort before cancellations are realised. | E24: Calculated
B25: Total Arriving Guests | C25: Total accepted bookings minus late cancellations. | D25: Represents guests who physically arrive and require accommodation. | E25: Calculated
B26: Occupied Rooms | C26: Number of rooms actually occupied, capped by Room Capacity. | D26: Actual occupancy cannot exceed the resort’s physical room capacity. | E26: Calculated
B27: Overbooked Guests | C27: Number of arriving guests who cannot be accommodated because physical capacity is exceeded. | D27: Overbooked guests occur only when arrivals exceed available rooms after cancellations are realised. | E27: Calculated
B28: Daily Sales Revenue | C28: Revenue generated from occupied rooms. | D28: Room revenue depends on occupied rooms and selected Room Price. | E28: Calculated
B29: Total Late Cancellation Fee Revenue | C29: Revenue collected from late cancellations. | D29: Cancellation fee revenue is generated when customers cancel within the late cancellation period. | E29: Calculated
B30: Total Overbooking Compensation Cost | C30: Total compensation paid to guests affected by overbooking. | D30: Compensation cost is incurred when arriving guests exceed physical room capacity and require compensation. | E30: Calculated
B31: Total Housekeeping Cost | C31: Occupied Rooms multiplied by Housekeeping Cost per Room. | D31: Captures variable room-servicing cost associated with actual occupancy. | E31: Calculated
B32: Total Daily Cost | C32: Total fixed operating cost, housekeeping cost, miscellaneous expenses, and compensation cost. | D32: Consolidates all daily operating costs required to calculate daily profit. | E32: Calculated
B34: OUTPUT
B35: Daily Profit | C35: Final daily profit after subtracting total daily cost from total revenue. | D35: Main financial performance measure used to evaluate profitability under different pricing and cancellation fee strategies. | E35: Calculated
B36: Sold Out Status | C36: Yes/No indicator showing whether all rooms are occupied. | D36: Provides a clear operational indicator of whether the resort fully utilised available room capacity. | E36: Calculated
B37: Compensation Required Status | C37: Yes/No indicator showing whether guests must be compensated due to overbooking. | D37: Highlights whether the selected booking policy creates customer displacement risk. | E37: Calculated
B38: Occupancy Rate | C38: Occupied Rooms divided by Room Capacity. | D38: Measures how effectively the resort uses available accommodation capacity. | E38: Calculated
B42: ADDITIONAL ASSUMPTIONS
B44: Additional Assumptions | C44: Justification
B45: The model represents one standard room type only. | C45: Simplifies the simulation structure while allowing focus on pricing, occupancy, and overbooking behaviour.
B46: The simulation represents a single peak-season operating day. | C46: Daily simulation allows direct analysis of operational uncertainty and short-term decision impacts during the June–August snow season.
B47: Customer demand remains relatively strong throughout the peak season. | C47: Victorian alpine resorts experience sustained accommodation demand during winter tourism periods, particularly during weekends and strong snow conditions.
B48: Online reservation demand represents booking requests rather than automatically confirmed reservations. | C48: This allows the resort to apply room capacity and overbooking constraints before accepting bookings.
B49: Walk-in guests arrive independently from online reservations. | C49: Walk-in demand is assumed to reflect spontaneous travel behaviour rather than pre-planned reservation demand.
...

Sheet 2. Probability Distributions
A1: PROBABILITY DISTRIBUTIONS
A2: Daily Online Reservations | H2: Walk-in Customers | R2: Number of Late Cancellations | AA2: Daily Miscellaneous Expenses
A4: Normal Distribution | H4: Poisson Distribution | R4: Binominal Distribution | AA4: Uniform Distribution
A6: Daily Online Reservations: Normal | I6: Walk-in customer: Poisson Distribution | AB6: Daily Miscellaneous Expenses: Uniform
S7: %Fulfillment at Late Cancellation Fee $100 | V7: 0.08 | W7: 100
C8: Standard | I8: Average Walk-in Guests (λ) | L8: 40 | S8: %Fulfillment at Late Cancellation Fee at $150 | V8: 0.05 | W8: 150 | AC8: Lower | AD8: Upper
B9: Mean | C9: deviation | AC9: limit | AD9: limit
A10: Price $499 | B10: 570 | C10: 48 | D10: 499 | E10: =ROUND(2.3,0) -> 2 | T10: 499 | U10: 100 | V10: Late Cancellations at $499+$100 Late Fee | W10: =RAND() -> 0.94698774 | X10: =_xlfn.BINOM.INV(D15,V7,W10) -> 57 | AB10: Uniform | AC10: 2000 | AD10: 5000
A11: Price $599 | B11: 510 | C11: 46 | D11: 599 | L11: Walk-in Guests | M11: =RAND() -> 0.53136881 | N11: =VLOOKUP(M11,J31:L130,3,TRUE) -> 39 | T11: 499 | U11: 150 | V11: Late Cancellations at $499+$150 Late Fee | W11: =RAND() -> 0.091129324 | X11: =_xlfn.BINOM.INV(D15,V8,W11) -> 22
T12: 599 | U12: 100 | V12: Late Cancellations at $599+$100 Late Fee | W12: =RAND() -> 0.91067627 | X12: =_xlfn.BINOM.INV(D16,V7,W12) -> 46
T13: 599 | U13: 150 | V13: Late Cancellations at $599+$150 Late Fee | W13: =RAND() -> 0.63470923 | X13: =_xlfn.BINOM.INV(D16,V8,W13) -> 25
AB14: Daily Miscellaneous Expenses | AC14: =RAND() -> 0.81864238 | AD14: =AC10+(AD10-AC10)*AC14 -> 4455.9272 | AE14: Uniform distribution
B15: Reservations when price $499 | C15: =RAND() -> 0.59244771 | D15: =MAX(0, INT(_xlfn.NORM.INV(C15,B10,C10))) -> 581 | E15: Normal distribution*
B16: Reservations when price $599 | C16: =RAND() -> 0.2303372 | D16: =MAX(0, INT(_xlfn.NORM.INV(C16,B11,C11))) -> 476 | E16: Normal distribution*
I30: Walkins | J30: Lower Limit | K30: Upper Limit | L30: Walkins
I31: 1 | J31: =_xlfn.POISSON.DIST(I31, '2. Probability Distributions'!$L$8, TRUE) -> 1.7418252e-16 | K31: =J32 -> 3.5728659e-15 | L31: 1
I32: 2 | J32: =_xlfn.POISSON.DIST(I32, '2. Probability Distributions'!$L$8, TRUE) -> 3.5728659e-15 | K32: =J33 -> 4.8888645e-14 | L32: 2
I33: 3 | J33: =_xlfn.POISSON.DIST(I33, '2. Probability Distributions'!$L$8, TRUE) -> 4.8888645e-14 | K33: =J34 -> 5.0204643e-13 | L33: 3
I34: 4 | J34: =_xlfn.POISSON.DIST(I34, '2. Probability Distributions'!$L$8, TRUE) -> 5.0204643e-13 | K34: =J35 -> 4.1273087e-12 | L34: 4
I35: 5 | J35: =_xlfn.POISSON.DIST(I35, '2. Probability Distributions'!$L$8, TRUE) -> 4.1273087e-12 | K35: =J36 -> 2.8295724e-11 | L35: 5
I36: 6 | J36: =_xlfn.POISSON.DIST(I36, '2. Probability Distributions'!$L$8, TRUE) -> 2.8295724e-11 | K36: =J37 -> 1.6640095e-10 | L36: 6
I37: 7 | J37: =_xlfn.POISSON.DIST(I37, '2. Probability Distributions'!$L$8, TRUE) -> 1.6640095e-10 | K37: =J38 -> 8.5692711e-10 | L37: 7
I38: 8 | J38: =_xlfn.POISSON.DIST(I38, '2. Probability Distributions'!$L$8, TRUE) -> 8.5692711e-10 | K38: =J39 -> 3.9259322e-09 | L38: 8
I39: 9 | J39: =_xlfn.POISSON.DIST(I39, '2. Probability Distributions'!$L$8, TRUE) -> 3.9259322e-09 | K39: =J40 -> 1.6201953e-08 | L39: 9
I40: 10 | J40: =_xlfn.POISSON.DIST(I40, '2. Probability Distributions'!$L$8, TRUE) -> 1.6201953e-08 | K40: =J41 -> 6.0842027e-08 | L40: 10
I41: 11 | J41: =_xlfn.POISSON.DIST(I41, '2. Probability Distributions'!$L$8, TRUE) -> 6.0842027e-08 | K41: =J42 -> 2.0964228e-07 | L41: 11
I42: 12 | J42: =_xlfn.POISSON.DIST(I42, '2. Probability Distributions'!$L$8, TRUE) -> 2.0964228e-07 | K42: =J43 -> 6.6748919e-07 | L42: 12
... I129: 99 | J129: =_xlfn.POISSON.DIST(I129, '2. Probability Distributions'!$L$8, TRUE) -> 1 | K129: =J130 -> 1 | L129: 99
I130: 100 | J130: =_xlfn.POISSON.DIST(I130, '2. Probability Distributions'!$L$8, TRUE) -> 1 | K130: 1 | L130: 100

Sheet 3. Model
B1: Stochastic model with Baseline values
B3: Intermediate Variables | C3: values | G3: INPUTS
B4: ='1. Manager Page'!B20 -> Available Booking Rooms | C4: =ROUND(H20*(1+H21),0) -> 482 | G4: Stochastic inputs | H4: values
B5: ='1. Manager Page'!B21 -> Accepted Online Reservations | C5: =IF(H5>C4,C4,H5) -> 482 | G5: ='1. Manager Page'!B3 -> Daily Online Reservations | H5: =IF(H13='2. Probability Distributions'!$D$10,'2. Probability Distributions'!$D$15,'2. Probability Distributions'!$D$16) -> 581 | I5: Normal Distribution
B6: ='1. Manager Page'!B22 -> Available Walk-ins Rooms | C6: =IF(C5<C4,C4-C5,0) -> 0 | G6: ='1. Manager Page'!B4 -> Walk-in Guests | H6: ='2. Probability Distributions'!$N$11 -> 39 | I6: Poisson Distribution
B7: ='1. Manager Page'!B23 -> Accepted Walk-in Guests | C7: =IF(H6>C6,C6,H6) -> 0 | G7: ='1. Manager Page'!B5 -> Late Cancellations | H7: {=_xlfn.XLOOKUP(1,('2. Probability Distributions'!T10:T13='3. Model'!H13)*('2. Probability Distributions'!U10:U13='3. Model'!H14),'2. Probability Distributions'!X10:X13)} -> 22 | I7: Binominal Distribution
B8: ='1. Manager Page'!B24 -> Total Accepted Bookings | C8: =C5+C7 -> 482 | G8: ='1. Manager Page'!B6 -> Daily Miscellaneous Expenses | H8: ='2. Probability Distributions'!$AD$14 -> 4455.9272 | I8: Uniform Distribution
B9: ='1. Manager Page'!B25 -> Total Arriving Guests | C9: =C8-H7 -> 460
B10: ='1. Manager Page'!B26 -> Occupied Rooms | C10: =IF(C9>H20,H20,C9) -> 450
B11: ='1. Manager Page'!B27 -> Overbooked Guests | C11: =IF(C9>H20,C9-H20,0) -> 10
B12: ='1. Manager Page'!B28 -> Daily Sales Revenue | C12: =C10*H13 -> 224550 | G12: Decision variables | H12: values
B13: ='1. Manager Page'!B29 -> Total Late Cancellation Fee Revenue | C13: =H7*H14 -> 3300 | G13: ='1. Manager Page'!B9 -> Room Price | H13: 499
B14: ='1. Manager Page'!B30 -> Total Overbooking Compensation Cost | C14: =C11*H13*H23 -> 4990 | G14: ='1. Manager Page'!B10 -> Late Cancellation Fee | H14: 150
B15: ='1. Manager Page'!B31 -> Total Housekeeping Cost | C15: =H22*C10 -> 45000
B16: ='1. Manager Page'!B32 -> Total Daily Cost | C16: =H24+C15+C14 -> 69990
B19: OUTPUT | G19: Fixed inputs | H19: values
B20: ='1. Manager Page'!B35 -> Daily Profit | C20: =C12+C13-C16 -> 157860 | G20: ='1. Manager Page'!B13 -> Room Capacity | H20: 450
B21: ='1. Manager Page'!B36 -> Sold Out Status | C21: =IF(H20>C10,"No","Yes") -> Yes | G21: ='1. Manager Page'!B14 -> Overbooking Rate | H21: 0.07
B22: ='1. Manager Page'!B37 -> Compensation Required Status | C22: =IF(C14>0,"Yes","No") -> Yes | G22: ='1. Manager Page'!B15 -> Housekeeping Cost per Room | H22: 100
B23: ='1. Manager Page'!B38 -> Occupancy Rate | C23: =C10/H20 -> 1 | G23: ='1. Manager Page'!B16 -> Compensation Cost Rule | H23: 1 | I23: (1 full room price)
G24: ='1. Manager Page'!B17 -> Daily Fixed Operating Cost | H24: 20000

Sheet 4.Simulated data
A1: Decision Value: Room Price $499 | H1: Room Price | I1: ='3. Model'!H13 -> 499 | Y1: Decision Value: Room Price $599
A3: Simulation on trials | B3: Daily Online Reservations | C3: Walk-in Guests | D3: Late Cancellations | E3: Daily Miscellaneous Expenses | F3: Occupied Rooms | G3: Overbooked Guests | H3: Daily Sales Revenue | I3: Total Daily Cost | J3: Daily Profit | K3: Sold Out Status | L3: Compensation Required Status | M3: Occupancy Rate | P3: Mean Occupied Rooms | Q3: Mean Overbooked Guest | R3: Mean Daily Sales Revenue | S3: Mean Total Daily Cost | T3: Mean Daily Profit | U3: Mean Occupancy Rate | Y3: Simulation on trials | Z3: Daily Online Reservations | AA3: Walk-in Guests | AB3: Late Cancellations | AC3: Daily Miscellaneous Expenses | AD3: Occupied Rooms | AE3: Overbooked Guests | AF3: Daily Sales Revenue | AG3: Total Daily Cost | AH3: Daily Profit | AI3: Sold Out Status | AJ3: Compensation Required Status | AK3: Occupancy Rate | AN3: Mean Occupied Rooms | AO3: Mean Overbooked Guest | AP3: Mean Daily Sales Revenue | AQ3: Mean Total Daily Cost | AR3: Mean Daily Profit | AS3: Mean Occupancy Rate
B4: ='3. Model'!H5 -> 581 | C4: ='3. Model'!H6 -> 39 | D4: ='3. Model'!H7 -> 22 | E4: ='3. Model'!H8 -> 4455.9272 | F4: ='3. Model'!C10 -> 450 | G4: ='3. Model'!C11 -> 10 | H4: ='3. Model'!C12 -> 224550 | I4: ='3. Model'!C16 -> 69990 | J4: ='3. Model'!C20 -> 157860 | K4: ='3. Model'!C21 -> Yes | L4: ='3. Model'!C22 -> Yes | M4: ='3. Model'!C23 -> 1 | Z4: ='3. Model'!H5 -> 581 | AA4: ='3. Model'!H6 -> 39 | AB4: ='3. Model'!H7 -> 22 | AC4: ='3. Model'!H8 -> 4455.9272 | AD4: ='3. Model'!C10 -> 450 | AE4: ='3. Model'!C11 -> 10 | AF4: ='3. Model'!C12 -> 224550 | AG4: ='3. Model'!C16 -> 69990 | AH4: ='3. Model'!C20 -> 157860 | AI4: ='3. Model'!C21 -> Yes | AJ4: ='3. Model'!C22 -> Yes | AK4: ='3. Model'!C23 -> 1
A5: 1 | B5: 590 | C5: 36 | D5: 21 | E5: 2922.2158 | F5: 450 | G5: 11 | H5: 224550 | I5: 70489 | J5: 157211 | K5: Yes | L5: Yes | M5: 1 | P5: =AVERAGE(F$5:F5) -> 450 | Q5: =AVERAGE(G$5:G5) -> 11 | R5: =AVERAGE(H$5:H5) -> 224550 | S5: =AVERAGE(I$5:I5) -> 70489 | T5: =AVERAGE(J$5:J5) -> 157211 | U5: =AVERAGE($M$5:M5) -> 1 | Y5: 1 | Z5: 547 | AA5: 26 | AB5: 25 | AC5: 3442.4996 | AD5: 450 | AE5: 7 | AF5: 224550 | AG5: 68493 | AH5: 159807 | AI5: Yes | AJ5: Yes | AK5: 1 | AN5: =AVERAGE(AD$5:AD5) -> 450 | AO5: =AVERAGE(AE$5:AE5) -> 7 | AP5: =AVERAGE(AF$5:AF5) -> 224550 | AQ5: =AVERAGE(AG$5:AG5) -> 68493 | AR5: =AVERAGE(AH$5:AH5) -> 159807 | AS5: =AVERAGE($AK$5:AK5) -> 1
A6: 2 | B6: 582 | C6: 30 | D6: 32 | E6: 3596.9159 | F6: 450 | G6: 0 | H6: 224550 | I6: 65000 | J6: 164350 | K6: Yes | L6: No | M6: 1 | P6: =AVERAGE(F$5:F6) -> 450 | Q6: =AVERAGE(G$5:G6) -> 5.5 | R6: =AVERAGE(H$5:H6) -> 224550 | S6: =AVERAGE(I$5:I6) -> 67744.5 | T6: =AVERAGE(J$5:J6) -> 160780.5 | U6: =AVERAGE($M$5:M6) -> 1 | Y6: 2 | Z6: 548 | AA6: 34 | AB6: 22 | AC6: 3601.293 | AD6: 450 | AE6: 10 | AF6: 224550 | AG6: 69990 | AH6: 157860 | AI6: Yes | AJ6: Yes | AK6: 1 | AN6: =AVERAGE(AD$5:AD6) -> 450 | AO6: =AVERAGE(AE$5:AE6) -> 8.5 | AP6: =AVERAGE(AF$5:AF6) -> 224550 | AQ6: =AVERAGE(AG$5:AG6) -> 69241.5 | AR6: =AVERAGE(AH$5:AH6) -> 158833.5 | AS6: =AVERAGE($AK$5:AK6) -> 1
A7: 3 | B7: 490 | C7: 37 | D7: 25 | E7: 2814.7386 | F7: 450 | G7: 7 | H7: 224550 | I7: 68493 | J7: 159807 | K7: Yes | L7: Yes | M7: 1 | P7: =AVERAGE(F$5:F7) -> 450 | Q7: =AVERAGE(G$5:G7) -> 6 | R7: =AVERAGE(H$5:H7) -> 224550 | S7: =AVERAGE(I$5:I7) -> 67994 | T7: =AVERAGE(J$5:J7) -> 160456 | U7: =AVERAGE($M$5:M7) -> 1 | Y7: 3 | Z7: 561 | AA7: 48 | AB7: 24 | AC7: 2214.5626 | AD7: 450 | AE7: 8 | AF7: 224550 | AG7: 68992 | AH7: 159158 | AI7: Yes | AJ7: Yes | AK7: 1 | AN7: =AVERAGE(AD$5:AD7) -> 450 | AO7: =AVERAGE(AE$5:AE7) -> 8.3333333 | AP7: =AVERAGE(AF$5:AF7) -> 224550 | AQ7: =AVERAGE(AG$5:AG7) -> 69158.333 | AR7: =AVERAGE(AH$5:AH7) -> 158941.67 | AS7: =AVERAGE($AK$5:AK7) -> 1
A8: 4 | B8: 518 | C8: 36 | D8: 24 | E8: 2572.9399 | F8: 450 | G8: 8 | H8: 224550 | I8: 68992 | J8: 159158 | K8: Yes | L8: Yes | M8: 1 | P8: =AVERAGE(F$5:F8) -> 450 | Q8: =AVERAGE(G$5:G8) -> 6.5 | R8: =AVERAGE(H$5:H8) -> 224550 | S8: =AVERAGE(I$5:I8) -> 68243.5 | T8: =AVERAGE(J$5:J8) -> 160131.5 | U8: =AVERAGE($M$5:M8) -> 1 | Y8: 4 | Z8: 561 | AA8: 34 | AB8: 32 | AC8: 4540.9141 | AD8: 450 | AE8: 0 | AF8: 224550 | AG8: 65000 | AH8: 164350 | AI8: Yes | AJ8: No | AK8: 1 | AN8: =AVERAGE(AD$5:AD8) -> 450 | AO8: =AVERAGE(AE$5:AE8) -> 6.25 | AP8: =AVERAGE(AF$5:AF8) -> 224550 | AQ8: =AVERAGE(AG$5:AG8) -> 68118.75 | AR8: =AVERAGE(AH$5:AH8) -> 160293.75 | AS8: =AVERAGE($AK$5:AK8) -> 1
A9: 5 | B9: 535 | C9: 39 | D9: 27 | E9: 3148.1816 | F9: 450 | G9: 5 | H9: 224550 | I9: 67495 | J9: 161105 | K9: Yes | L9: Yes | M9: 1 | P9: =AVERAGE(F$5:F9) -> 450 | Q9: =AVERAGE(G$5:G9) -> 6.2 | R9: =AVERAGE(H$5:H9) -> 224550 | S9: =AVERAGE(I$5:I9) -> 68093.8 | T9: =AVERAGE(J$5:J9) -> 160326.2 | U9: =AVERAGE($M$5:M9) -> 1 | Y9: 5 | Z9: 723 | AA9: 33 | AB9: 44 | AC9: 3311.6409 | AD9: 438 | AE9: 0 | AF9: 218562 | AG9: 63800 | AH9: 161362 | AI9: No | AJ9: No | AK9: 0.97333333 | AN9: =AVERAGE(AD$5:AD9) -> 447.6 | AO9: =AVERAGE(AE$5:AE9) -> 5 | AP9: =AVERAGE(AF$5:AF9) -> 223352.4 | AQ9: =AVERAGE(AG$5:AG9) -> 67255 | AR9: =AVERAGE(AH$5:AH9) -> 160507.4 | AS9: =AVERAGE($AK$5:AK9) -> 0.99466667
A10: 6 | B10: 474 | C10: 31 | D10: 31 | E10: 3821.4417 | F10: 450 | G10: 1 | H10: 224550 | I10: 65499 | J10: 163701 | K10: Yes | L10: Yes | M10: 1 | P10: =AVERAGE(F$5:F10) -> 450 | Q10: =AVERAGE(G$5:G10) -> 5.3333333 | R10: =AVERAGE(H$5:H10) -> 224550 | S10: =AVERAGE(I$5:I10) -> 67661.333 | T10: =AVERAGE(J$5:J10) -> 160888.67 | U10: =AVERAGE($M$5:M10) -> 1 | Y10: 6 | Z10: 499 | AA10: 40 | AB10: 34 | AC10: 2959.5056 | AD10: 448 | AE10: 0 | AF10: 223552 | AG10: 64800 | AH10: 163852 | AI10: No | AJ10: No | AK10: 0.99555556 | AN10: =AVERAGE(AD$5:AD10) -> 447.66667 | AO10: =AVERAGE(AE$5:AE10) -> 4.1666667 | AP10: =AVERAGE(AF$5:AF10) -> 223385.67 | AQ10: =AVERAGE(AG$5:AG10) -> 66845.833 | AR10: =AVERAGE(AH$5:AH10) -> 161064.83 | AS10: =AVERAGE($AK$5:AK10) -> 0.99481481
A11: 7 | B11: 562 | C11: 39 | D11: 19 | E11: 2202.3204 | F11: 450 | G11: 13 | H11: 224550 | I11: 71487 | J11: 155913 | K11: Yes | L11: Yes | M11: 1 | P11: =AVERAGE(F$5:F11) -> 450 | Q11: =AVERAGE(G$5:G11) -> 6.4285714 | R11: =AVERAGE(H$5:H11) -> 224550 | S11: =AVERAGE(I$5:I11) -> 68207.857 | T11: =AVERAGE(J$5:J11) -> 160177.86 | U11: =AVERAGE($M$5:M11) -> 1 | Y11: 7 | Z11: 532 | AA11: 35 | AB11: 34 | AC11: 3062.815 | AD11: 448 | AE11: 0 | AF11: 223552 | AG11: 64800 | AH11: 163852 | AI11: No | AJ11: No | AK11: 0.99555556 | AN11: =AVERAGE(AD$5:AD11) -> 447.71429 | AO11: =AVERAGE(AE$5:AE11) -> 3.5714286 | AP11: =AVERAGE(AF$5:AF11) -> 223409.43 | AQ11: =AVERAGE(AG$5:AG11) -> 66553.571 | AR11: =AVERAGE(AH$5:AH11) -> 161463 | AS11: =AVERAGE($AK$5:AK11) -> 0.99492063
A12: 8 | B12: 676 | C12: 34 | D12: 38 | E12: 2122.3806 | F12: 444 | G12: 0 | H12: 221556 | I12: 64400 | J12: 162856 | K12: No | L12: No | M12: 0.98666667 | P12: =AVERAGE(F$5:F12) -> 449.25 | Q12: =AVERAGE(G$5:G12) -> 5.625 | R12: =AVERAGE(H$5:H12) -> 224175.75 | S12: =AVERAGE(I$5:I12) -> 67731.875 | T12: =AVERAGE(J$5:J12) -> 160512.62 | U12: =AVERAGE($M$5:M12) -> 0.99833333 | Y12: 8 | Z12: 554 | AA12: 39 | AB12: 26 | AC12: 3671.2375 | AD12: 450 | AE12: 6 | AF12: 224550 | AG12: 67994 | AH12: 160456 | AI12: Yes | AJ12: Yes | AK12: 1 | AN12: =AVERAGE(AD$5:AD12) -> 448 | AO12: =AVERAGE(AE$5:AE12) -> 3.875 | AP12: =AVERAGE(AF$5:AF12) -> 223552 | AQ12: =AVERAGE(AG$5:AG12) -> 66733.625 | AR12: =AVERAGE(AH$5:AH12) -> 161337.12 | AS12: =AVERAGE($AK$5:AK12) -> 0.99555556
A13: 9 | B13: 660 | C13: 48 | D13: 34 | E13: 2028.83 | F13: 448 | G13: 0 | H13: 223552 | I13: 64800 | J13: 163852 | K13: No | L13: No | M13: 0.99555556 | P13: =AVERAGE(F$5:F13) -> 449.11111 | Q13: =AVERAGE(G$5:G13) -> 5 | R13: =AVERAGE(H$5:H13) -> 224106.44 | S13: =AVERAGE(I$5:I13) -> 67406.111 | T13: =AVERAGE(J$5:J13) -> 160883.67 | U13: =AVERAGE($M$5:M13) -> 0.99802469 | Y13: 9 | Z13: 608 | AA13: 38 | AB13: 32 | AC13: 4447.5716 | AD13: 450 | AE13: 0 | AF13: 224550 | AG13: 65000 | AH13: 164350 | AI13: Yes | AJ13: No | AK13: 1 | AN13: =AVERAGE(AD$5:AD13) -> 448.22222 | AO13: =AVERAGE(AE$5:AE13) -> 3.4444444 | AP13: =AVERAGE(AF$5:AF13) -> 223662.89 | AQ13: =AVERAGE(AG$5:AG13) -> 66541 | AR13: =AVERAGE(AH$5:AH13) -> 161671.89 | AS13: =AVERAGE($AK$5:AK13) -> 0.99604938
A14: 10 | B14: 530 | C14: 46 | D14: 29 | E14: 4242.8658 | F14: 450 | G14: 3 | H14: 224550 | I14: 66497 | J14: 162403 | K14: Yes | L14: Yes | M14: 1 | P14: =AVERAGE(F$5:F14) -> 449.2 | Q14: =AVERAGE(G$5:G14) -> 4.8 | R14: =AVERAGE(H$5:H14) -> 224150.8 | S14: =AVERAGE(I$5:I14) -> 67315.2 | T14: =AVERAGE(J$5:J14) -> 161035.6 | U14: =AVERAGE($M$5:M14) -> 0.99822222 | Y14: 10 | Z14: 531 | AA14: 40 | AB14: 16 | AC14: 2771.8508 | AD14: 450 | AE14: 16 | AF14: 224550 | AG14: 72984 | AH14: 153966 | AI14: Yes | AJ14: Yes | AK14: 1 | AN14: =AVERAGE(AD$5:AD14) -> 448.4 | AO14: =AVERAGE(AE$5:AE14) -> 4.7 | AP14: =AVERAGE(AF$5:AF14) -> 223751.6 | AQ14: =AVERAGE(AG$5:AG14) -> 67185.3 | AR14: =AVERAGE(AH$5:AH14) -> 160901.3 | AS14: =AVERAGE($AK$5:AK14) -> 0.99644444
A15: 11 | B15: 519 | C15: 32 | D15: 32 | E15: 2505.886 | F15: 450 | G15: 0 | H15: 224550 | I15: 65000 | J15: 164350 | K15: Yes | L15: No | M15: 1 | P15: =AVERAGE(F$5:F15) -> 449.27273 | Q15: =AVERAGE(G$5:G15) -> 4.3636364 | R15: =AVERAGE(H$5:H15) -> 224187.09 | S15: =AVERAGE(I$5:I15) -> 67104.727 | T15: =AVERAGE(J$5:J15) -> 161336.91 | U15: =AVERAGE($M$5:M15) -> 0.99838384 | Y15: 11 | Z15: 573 | AA15: 43 | AB15: 24 | AC15: 4374.0117 | AD15: 450 | AE15: 8 | AF15: 224550 | AG15: 68992 | AH15: 159158 | AI15: Yes | AJ15: Yes | AK15: 1 | AN15: =AVERAGE(AD$5:AD15) -> 448.54545 | AO15: =AVERAGE(AE$5:AE15) -> 5 | AP15: =AVERAGE(AF$5:AF15) -> 223824.18 | AQ15: =AVERAGE(AG$5:AG15) -> 67349.545 | AR15: =AVERAGE(AH$5:AH15) -> 160742.82 | AS15: =AVERAGE($AK$5:AK15) -> 0.99676768
A16: 12 | B16: 561 | C16: 39 | D16: 29 | E16: 2735.7148 | F16: 450 | G16: 3 | H16: 224550 | I16: 66497 | J16: 162403 | K16: Yes | L16: Yes | M16: 1 | P16: =AVERAGE(F$5:F16) -> 449.33333 | Q16: =AVERAGE(G$5:G16) -> 4.25 | R16: =AVERAGE(H$5:H16) -> 224217.33 | S16: =AVERAGE(I$5:I16) -> 67054.083 | T16: =AVERAGE(J$5:J16) -> 161425.75 | U16: =AVERAGE($M$5:M16) -> 0.99851852 | Y16: 12 | Z16: 540 | AA16: 24 | AB16: 30 | AC16: 3479.5204 | AD16: 450 | AE16: 2 | AF16: 224550 | AG16: 65998 | AH16: 163052 | AI16: Yes | AJ16: Yes | AK16: 1 | AN16: =AVERAGE(AD$5:AD16) -> 448.66667 | AO16: =AVERAGE(AE$5:AE16) -> 4.75 | AP16: =AVERAGE(AF$5:AF16) -> 223884.67 | AQ16: =AVERAGE(AG$5:AG16) -> 67236.917 | AR16: =AVERAGE(AH$5:AH16) -> 160935.25 | AS16: =AVERAGE($AK$5:AK16) -> 0.99703704
... A1004: 1000 | B1004: 629 | C1004: 34 | D1004: 30 | E1004: 4587.1987 | F1004: 450 | G1004: 2 | H1004: 224550 | I1004: 65998 | J1004: 163052 | K1004: Yes | L1004: Yes | M1004: 1 | P1004: =AVERAGE(F$5:F1004) -> 448.976 | Q1004: =AVERAGE(G$5:G1004) -> 4.553 | R1004: =AVERAGE(H$5:H1004) -> 224039.02 | S1004: =AVERAGE(I$5:I1004) -> 67169.547 | T1004: =AVERAGE(J$5:J1004) -> 161129.93 | U1004: =AVERAGE($M$5:M1004) -> 0.99772444 | Y1004: 1000 | Z1004: 656 | AA1004: 44 | AB1004: 36 | AC1004: 2743.112 | AD1004: 446 | AE1004: 0 | AF1004: 222554 | AG1004: 64600 | AH1004: 163354 | AI1004: No | AJ1004: No | AK1004: 0.99111111 | AN1004: =AVERAGE(AD$5:AD1004) -> 449.1 | AO1004: =AVERAGE(AE$5:AE1004) -> 4.522 | AP1004: =AVERAGE(AF$5:AF1004) -> 224100.9 | AQ1004: =AVERAGE(AG$5:AG1004) -> 67166.478 | AR1004: =AVERAGE(AH$5:AH1004) -> 161187.22 | AS1004: =AVERAGE($AK$5:AK1004) -> 0.998

Sheet 5.Simulation-fixed values
A1: Decision Value: Room Price $499 | H1: Room Price | I1: 499 | AH1: Decision Value: Room Price $599 | AO1: Room Price | AP1: 599
A3: Simulation on trials | B3: Daily Online Reservations | C3: Walk-in Guests | D3: Late Cancellations | E3: Daily Miscellaneous Expenses | F3: Occupied Rooms | G3: Overbooked Guests | H3: Daily Sales Revenue | I3: Total Daily Cost | J3: Daily Profit | K3: Sold Out Status | L3: Compensation Required Status | M3: Occupancy Rate | P3: Mean Occupied Rooms | Q3: Mean Overbooked Guest | R3: Mean Daily Sales Revenue | S3: Mean Total Daily Cost | T3: Mean Daily Profit | U3: Mean Occupancy Rate | AH3: Simulation on trials | AI3: Daily Online Reservations | AJ3: Walk-in Guests | AK3: Late Cancellations | AL3: Daily Miscellaneous Expenses | AM3: Occupied Rooms | AN3: Overbooked Guests | AO3: Daily Sales Revenue | AP3: Total Daily Cost | AQ3: Daily Profit | AR3: Sold Out Status | AS3: Compensation Required Status | AT3: Occupancy Rate | AW3: Mean Occupied Rooms | AX3: Mean Overbooked Guest | AY3: Mean Daily Sales Revenue | AZ3: Mean Total Daily Cost | BA3: Mean Daily Profit | BB3: Mean Occupancy Rate
B4: 580 | C4: 46 | D4: 40 | E4: 3502.6262 | F4: 442 | G4: 0 | H4: 220558 | I4: 64200 | J4: 160358 | K4: No | L4: No | M4: 0.98222222 | AI4: 523 | AJ4: 41 | AK4: 40 | AL4: 2124.6374 | AM4: 442 | AN4: 0 | AO4: 264758 | AP4: 64200 | AQ4: 204558 | AR4: No | AS4: No | AT4: 0.98222222
A5: 1 | B5: 567 | C5: 45 | D5: 48 | E5: 2531.7161 | F5: 434 | G5: 0 | H5: 216566 | I5: 63400 | J5: 157966 | K5: No | L5: No | M5: 0.96444444 | P5: =AVERAGE(F$5:F5) -> 434 | Q5: =AVERAGE(G$5:G5) -> 0 | R5: =AVERAGE(H$5:H5) -> 216566 | S5: =AVERAGE(I$5:I5) -> 63400 | T5: =AVERAGE(J$5:J5) -> 157966 | U5: =AVERAGE($M$5:M5) -> 0.96444444 | AH5: 1 | AI5: 498 | AJ5: 43 | AK5: 40 | AL5: 3734.1299 | AM5: 442 | AN5: 0 | AO5: 264758 | AP5: 64200 | AQ5: 204558 | AR5: No | AS5: No | AT5: 0.98222222 | AW5: =AVERAGE(AM$5:AM5) -> 442 | AX5: =AVERAGE(AN$5:AN5) -> 0 | AY5: =AVERAGE(AO$5:AO5) -> 264758 | AZ5: =AVERAGE(AP$5:AP5) -> 64200 | BA5: =AVERAGE(AQ$5:AQ5) -> 204558 | BB5: =AVERAGE($AT$5:AT5) -> 0.98222222
A6: 2 | B6: 562 | C6: 48 | D6: 51 | E6: 3610.644 | F6: 431 | G6: 0 | H6: 215069 | I6: 63100 | J6: 157069 | K6: No | L6: No | M6: 0.95777778 | P6: =AVERAGE($F$5:F6) -> 432.5 | Q6: =AVERAGE(G$5:G6) -> 0 | R6: =AVERAGE(H$5:H6) -> 215817.5 | S6: =AVERAGE(I$5:I6) -> 63250 | T6: =AVERAGE(J$5:J6) -> 157517.5 | U6: =AVERAGE($M$5:M6) -> 0.96111111 | AH6: 2 | AI6: 468 | AJ6: 43 | AK6: 46 | AL6: 4720.8085 | AM6: 436 | AN6: 0 | AO6: 261164 | AP6: 63600 | AQ6: 202164 | AR6: No | AS6: No | AT6: 0.96888889 | AW6: =AVERAGE(AM$5:AM6) -> 439 | AX6: =AVERAGE(AN$5:AN6) -> 0 | AY6: =AVERAGE(AO$5:AO6) -> 262961 | AZ6: =AVERAGE(AP$5:AP6) -> 63900 | BA6: =AVERAGE(AQ$5:AQ6) -> 203361 | BB6: =AVERAGE($AT$5:AT6) -> 0.97555556
A7: 3 | B7: 560 | C7: 32 | D7: 50 | E7: 2124.954 | F7: 432 | G7: 0 | H7: 215568 | I7: 63200 | J7: 157368 | K7: No | L7: No | M7: 0.96 | P7: =AVERAGE($F$5:F7) -> 432.33333 | Q7: =AVERAGE(G$5:G7) -> 0 | R7: =AVERAGE(H$5:H7) -> 215734.33 | S7: =AVERAGE(I$5:I7) -> 63233.333 | T7: =AVERAGE(J$5:J7) -> 157467.67 | U7: =AVERAGE($M$5:M7) -> 0.96074074 | AH7: 3 | AI7: 465 | AJ7: 49 | AK7: 38 | AL7: 4105.8116 | AM7: 444 | AN7: 0 | AO7: 265956 | AP7: 64400 | AQ7: 205356 | AR7: No | AS7: No | AT7: 0.98666667 | AW7: =AVERAGE(AM$5:AM7) -> 440.66667 | AX7: =AVERAGE(AN$5:AN7) -> 0 | AY7: =AVERAGE(AO$5:AO7) -> 263959.33 | AZ7: =AVERAGE(AP$5:AP7) -> 64066.667 | BA7: =AVERAGE(AQ$5:AQ7) -> 204026 | BB7: =AVERAGE($AT$5:AT7) -> 0.97925926
A8: 4 | B8: 532 | C8: 33 | D8: 35 | E8: 2357.2768 | F8: 447 | G8: 0 | H8: 223053 | I8: 64700 | J8: 161853 | K8: No | L8: No | M8: 0.99333333 | P8: =AVERAGE($F$5:F8) -> 436 | Q8: =AVERAGE(G$5:G8) -> 0 | R8: =AVERAGE(H$5:H8) -> 217564 | S8: =AVERAGE(I$5:I8) -> 63600 | T8: =AVERAGE(J$5:J8) -> 158564 | U8: =AVERAGE($M$5:M8) -> 0.96888889 | AH8: 4 | AI8: 502 | AJ8: 38 | AK8: 35 | AL8: 2368.9417 | AM8: 447 | AN8: 0 | AO8: 267753 | AP8: 64700 | AQ8: 206553 | AR8: No | AS8: No | AT8: 0.99333333 | AW8: =AVERAGE(AM$5:AM8) -> 442.25 | AX8: =AVERAGE(AN$5:AN8) -> 0 | AY8: =AVERAGE(AO$5:AO8) -> 264907.75 | AZ8: =AVERAGE(AP$5:AP8) -> 64225 | BA8: =AVERAGE(AQ$5:AQ8) -> 204657.75 | BB8: =AVERAGE($AT$5:AT8) -> 0.98277778
A9: 5 | B9: 635 | C9: 31 | D9: 45 | E9: 3910.2728 | F9: 437 | G9: 0 | H9: 218063 | I9: 63700 | J9: 158863 | K9: No | L9: No | M9: 0.97111111 | P9: =AVERAGE($F$5:F9) -> 436.2 | Q9: =AVERAGE(G$5:G9) -> 0 | R9: =AVERAGE(H$5:H9) -> 217663.8 | S9: =AVERAGE(I$5:I9) -> 63620 | T9: =AVERAGE(J$5:J9) -> 158623.8 | U9: =AVERAGE($M$5:M9) -> 0.96933333 | AH9: 5 | AI9: 611 | AJ9: 44 | AK9: 52 | AL9: 2492.689 | AM9: 430 | AN9: 0 | AO9: 257570 | AP9: 63000 | AQ9: 199770 | AR9: No | AS9: No | AT9: 0.95555556 | AW9: =AVERAGE(AM$5:AM9) -> 439.8 | AX9: =AVERAGE(AN$5:AN9) -> 0 | AY9: =AVERAGE(AO$5:AO9) -> 263440.2 | AZ9: =AVERAGE(AP$5:AP9) -> 63980 | BA9: =AVERAGE(AQ$5:AQ9) -> 203680.2 | BB9: =AVERAGE($AT$5:AT9) -> 0.97733333
A10: 6 | B10: 592 | C10: 34 | D10: 54 | E10: 2275.0026 | F10: 428 | G10: 0 | H10: 213572 | I10: 62800 | J10: 156172 | K10: No | L10: No | M10: 0.95111111 | P10: =AVERAGE($F$5:F10) -> 434.83333 | Q10: =AVERAGE(G$5:G10) -> 0 | R10: =AVERAGE(H$5:H10) -> 216981.83 | S10: =AVERAGE(I$5:I10) -> 63483.333 | T10: =AVERAGE(J$5:J10) -> 158215.17 | U10: =AVERAGE($M$5:M10) -> 0.9662963 | AH10: 6 | AI10: 485 | AJ10: 43 | AK10: 42 | AL10: 2210.0838 | AM10: 440 | AN10: 0 | AO10: 263560 | AP10: 64000 | AQ10: 203760 | AR10: No | AS10: No | AT10: 0.97777778 | AW10: =AVERAGE(AM$5:AM10) -> 439.83333 | AX10: =AVERAGE(AN$5:AN10) -> 0 | AY10: =AVERAGE(AO$5:AO10) -> 263460.17 | AZ10: =AVERAGE(AP$5:AP10) -> 63983.333 | BA10: =AVERAGE(AQ$5:AQ10) -> 203693.5 | BB10: =AVERAGE($AT$5:AT10) -> 0.97740741
A11: 7 | B11: 594 | C11: 30 | D11: 42 | E11: 4850.6422 | F11: 440 | G11: 0 | H11: 219560 | I11: 64000 | J11: 159760 | K11: No | L11: No | M11: 0.97777778 | P11: =AVERAGE($F$5:F11) -> 435.57143 | Q11: =AVERAGE(G$5:G11) -> 0 | R11: =AVERAGE(H$5:H11) -> 217350.14 | S11: =AVERAGE(I$5:I11) -> 63557.143 | T11: =AVERAGE(J$5:J11) -> 158435.86 | U11: =AVERAGE($M$5:M11) -> 0.96793651 | AH11: 7 | AI11: 479 | AJ11: 39 | AK11: 34 | AL11: 3506.3912 | AM11: 448 | AN11: 0 | AO11: 268352 | AP11: 64800 | AQ11: 206952 | AR11: No | AS11: No | AT11: 0.99555556 | AW11: =AVERAGE(AM$5:AM11) -> 441 | AX11: =AVERAGE(AN$5:AN11) -> 0 | AY11: =AVERAGE(AO$5:AO11) -> 264159 | AZ11: =AVERAGE(AP$5:AP11) -> 64100 | BA11: =AVERAGE(AQ$5:AQ11) -> 204159 | BB11: =AVERAGE($AT$5:AT11) -> 0.98
A12: 8 | B12: 572 | C12: 40 | D12: 46 | E12: 2181.7436 | F12: 436 | G12: 0 | H12: 217564 | I12: 63600 | J12: 158564 | K12: No | L12: No | M12: 0.96888889 | P12: =AVERAGE($F$5:F12) -> 435.625 | Q12: =AVERAGE(G$5:G12) -> 0 | R12: =AVERAGE(H$5:H12) -> 217376.88 | S12: =AVERAGE(I$5:I12) -> 63562.5 | T12: =AVERAGE(J$5:J12) -> 158451.88 | U12: =AVERAGE($M$5:M12) -> 0.96805556 | AH12: 8 | AI12: 480 | AJ12: 35 | AK12: 40 | AL12: 4757.0963 | AM12: 442 | AN12: 0 | AO12: 264758 | AP12: 64200 | AQ12: 204558 | AR12: No | AS12: No | AT12: 0.98222222 | AW12: =AVERAGE(AM$5:AM12) -> 441.125 | AX12: =AVERAGE(AN$5:AN12) -> 0 | AY12: =AVERAGE(AO$5:AO12) -> 264233.88 | AZ12: =AVERAGE(AP$5:AP12) -> 64112.5 | BA12: =AVERAGE(AQ$5:AQ12) -> 204208.88 | BB12: =AVERAGE($AT$5:AT12) -> 0.98027778
A13: 9 | B13: 589 | C13: 38 | D13: 58 | E13: 3429.9487 | F13: 424 | G13: 0 | H13: 211576 | I13: 62400 | J13: 154976 | K13: No | L13: No | M13: 0.94222222 | P13: =AVERAGE($F$5:F13) -> 434.33333 | Q13: =AVERAGE(G$5:G13) -> 0 | R13: =AVERAGE(H$5:H13) -> 216732.33 | S13: =AVERAGE(I$5:I13) -> 63433.333 | T13: =AVERAGE(J$5:J13) -> 158065.67 | U13: =AVERAGE($M$5:M13) -> 0.96518519 | AH13: 9 | AI13: 472 | AJ13: 48 | AK13: 47 | AL13: 2622.8211 | AM13: 435 | AN13: 0 | AO13: 260565 | AP13: 63500 | AQ13: 201765 | AR13: No | AS13: No | AT13: 0.96666667 | AW13: =AVERAGE(AM$5:AM13) -> 440.44444 | AX13: =AVERAGE(AN$5:AN13) -> 0 | AY13: =AVERAGE(AO$5:AO13) -> 263826.22 | AZ13: =AVERAGE(AP$5:AP13) -> 64044.444 | BA13: =AVERAGE(AQ$5:AQ13) -> 203937.33 | BB13: =AVERAGE($AT$5:AT13) -> 0.97876543
A14: 10 | B14: 618 | C14: 27 | D14: 57 | E14: 2368.3822 | F14: 425 | G14: 0 | H14: 212075 | I14: 62500 | J14: 155275 | K14: No | L14: No | M14: 0.94444444 | P14: =AVERAGE($F$5:F14) -> 433.4 | Q14: =AVERAGE(G$5:G14) -> 0 | R14: =AVERAGE(H$5:H14) -> 216266.6 | S14: =AVERAGE(I$5:I14) -> 63340 | T14: =AVERAGE(J$5:J14) -> 157786.6 | U14: =AVERAGE($M$5:M14) -> 0.96311111 | AH14: 10 | AI14: 537 | AJ14: 40 | AK14: 40 | AL14: 2070.7363 | AM14: 442 | AN14: 0 | AO14: 264758 | AP14: 64200 | AQ14: 204558 | AR14: No | AS14: No | AT14: 0.98222222 | AW14: =AVERAGE(AM$5:AM14) -> 440.6 | AX14: =AVERAGE(AN$5:AN14) -> 0 | AY14: =AVERAGE(AO$5:AO14) -> 263919.4 | AZ14: =AVERAGE(AP$5:AP14) -> 64060 | BA14: =AVERAGE(AQ$5:AQ14) -> 203999.4 | BB14: =AVERAGE($AT$5:AT14) -> 0.97911111
A15: 11 | B15: 492 | C15: 34 | D15: 28 | E15: 4306.6467 | F15: 450 | G15: 4 | H15: 224550 | I15: 66996 | J15: 160354 | K15: Yes | L15: Yes | M15: 1 | P15: =AVERAGE($F$5:F15) -> 434.90909 | Q15: =AVERAGE(G$5:G15) -> 0.36363636 | R15: =AVERAGE(H$5:H15) -> 217019.64 | S15: =AVERAGE(I$5:I15) -> 63672.364 | T15: =AVERAGE(J$5:J15) -> 158020 | U15: =AVERAGE($M$5:M15) -> 0.96646465 | AH15: 11 | AI15: 496 | AJ15: 33 | AK15: 40 | AL15: 2719.9487 | AM15: 442 | AN15: 0 | AO15: 264758 | AP15: 64200 | AQ15: 204558 | AR15: No | AS15: No | AT15: 0.98222222 | AW15: =AVERAGE(AM$5:AM15) -> 440.72727 | AX15: =AVERAGE(AN$5:AN15) -> 0 | AY15: =AVERAGE(AO$5:AO15) -> 263995.64 | AZ15: =AVERAGE(AP$5:AP15) -> 64072.727 | BA15: =AVERAGE(AQ$5:AQ15) -> 204050.18 | BB15: =AVERAGE($AT$5:AT15) -> 0.97939394
A16: 12 | B16: 583 | C16: 46 | D16: 48 | E16: 2579.2058 | F16: 434 | G16: 0 | H16: 216566 | I16: 63400 | J16: 157966 | K16: No | L16: No | M16: 0.96444444 | P16: =AVERAGE($F$5:F16) -> 434.83333 | Q16: =AVERAGE(G$5:G16) -> 0.33333333 | R16: =AVERAGE(H$5:H16) -> 216981.83 | S16: =AVERAGE(I$5:I16) -> 63649.667 | T16: =AVERAGE(J$5:J16) -> 158015.5 | U16: =AVERAGE($M$5:M16) -> 0.9662963 | AH16: 12 | AI16: 480 | AJ16: 21 | AK16: 41 | AL16: 2448.6102 | AM16: 441 | AN16: 0 | AO16: 264159 | AP16: 64100 | AQ16: 204159 | AR16: No | AS16: No | AT16: 0.98 | AW16: =AVERAGE(AM$5:AM16) -> 440.75 | AX16: =AVERAGE(AN$5:AN16) -> 0 | AY16: =AVERAGE(AO$5:AO16) -> 264009.25 | AZ16: =AVERAGE(AP$5:AP16) -> 64075 | BA16: =AVERAGE(AQ$5:AQ16) -> 204059.25 | BB16: =AVERAGE($AT$5:AT16) -> 0.97944444
A17: 13 | B17: 574 | C17: 34 | D17: 52 | E17: 3105.061 | F17: 430 | G17: 0 | H17: 214570 | I17: 63000 | J17: 156770 | K17: No | L17: No | M17: 0.95555556 | P17: =AVERAGE($F$5:F17) -> 434.46154 | Q17: =AVERAGE(G$5:G17) -> 0.30769231 | R17: =AVERAGE(H$5:H17) -> 216796.31 | S17: =AVERAGE(I$5:I17) -> 63599.692 | T17: =AVERAGE(J$5:J17) -> 157919.69 | U17: =AVERAGE($M$5:M17) -> 0.96547009 | AH17: 13 | AI17: 486 | AJ17: 47 | AK17: 38 | AL17: 3153.5232 | AM17: 444 | AN17: 0 | AO17: 265956 | AP17: 64400 | AQ17: 205356 | AR17: No | AS17: No | AT17: 0.98666667 | AW17: =AVERAGE(AM$5:AM17) -> 441 | AX17: =AVERAGE(AN$5:AN17) -> 0 | AY17: =AVERAGE(AO$5:AO17) -> 264159 | AZ17: =AVERAGE(AP$5:AP17) -> 64100 | BA17: =AVERAGE(AQ$5:AQ17) -> 204159 | BB17: =AVERAGE($AT$5:AT17) -> 0.98
... A1004: 1000 | B1004: 626 | C1004: 37 | D1004: 45 | E1004: 4127.432 | F1004: 437 | G1004: 0 | H1004: 218063 | I1004: 63700 | J1004: 158863 | K1004: No | L1004: No | M1004: 0.97111111 | P1004: =AVERAGE($F$5:F1004) -> 436.271 | Q1004: =AVERAGE(G$5:G1004) -> 0.049 | R1004: =AVERAGE(H$5:H1004) -> 217699.23 | S1004: =AVERAGE(I$5:I1004) -> 63651.551 | T1004: =AVERAGE(J$5:J1004) -> 158615.68 | U1004: =AVERAGE($M$5:M1004) -> 0.96949111 | AH1004: 1000 | AI1004: 500 | AJ1004: 38 | AK1004: 36 | AL1004: 3959.8129 | AM1004: 446 | AN1004: 0 | AO1004: 267154 | AP1004: 64600 | AQ1004: 206154 | AR1004: No | AS1004: No | AT1004: 0.99111111 | AW1004: =AVERAGE(AM$5:AM1004) -> 439.869 | AX1004: =AVERAGE(AN$5:AN1004) -> 0.265 | AY1004: =AVERAGE(AO$5:AO1004) -> 263481.53 | AZ1004: =AVERAGE(AP$5:AP1004) -> 64145.635 | BA1004: =AVERAGE(AQ$5:AQ1004) -> 203403.4 | BB1004: =AVERAGE($AT$5:AT1004) -> 0.97748667

Sheet 6.  Risk Analysis
E1: RISK PROFILING based on SIMULATED OUTPUT (constant values in Section 5)
B3: Profit intervals when Room Price is $499 | M3: Profit intervals when Room Price is $599
B5: Output/Profit | C5: Loss ( <0K) | D5: 0K - 150K | E5: $150K - $155K | F5: $155K - $158K | G5: $158K - $162K | H5: Over $162K | I5: Total | M5: Output/Profit | N5: Loss ( <0K) | O5: 0K - 180K | P5: $180K - $190K | Q5: $190K - $200K | R5: $200K - $210K | S5: Over $210K | T5: Total
B6: Probability | C6: =COUNTIF('5.Simulation-fixed values'!$J$5:$J$1004, "<00000")/1000 -> 0 | D6: =COUNTIF('5.Simulation-fixed values'!$J$5:$J$1004, "<150000")/1000-C6 -> 0 | E6: =COUNTIF('5.Simulation-fixed values'!$J$5:$J$1004, "<155000")/1000-D6-C6 -> 0.051 | F6: =COUNTIF('5.Simulation-fixed values'!$J$5:$J$1004, "<158000")/1000-D6-E6-C6 -> 0.344 | G6: =COUNTIF('5.Simulation-fixed values'!$J$5:$J$1004, "<162000")/1000-D6-E6-F6-C6 -> 0.553 | H6: =1-D6-E6-F6-G6-C6 -> 0.052 | I6: =SUM(C6:H6) -> 1 | M6: Probability | N6: =COUNTIF('5.Simulation-fixed values'!$AQ$5:$AQ$1004, "<00000")/1000 -> 0 | O6: =COUNTIF('5.Simulation-fixed values'!$AQ$5:$AQ$1004, "<180000")/1000-N6 -> 0.002 | P6: =COUNTIF('5.Simulation-fixed values'!$AQ$5:$AQ$1004, "<190000")/1000-O6-N6 -> 0.009 | Q6: =COUNTIF('5.Simulation-fixed values'!$AQ$5:$AQ$1004, "<200000")/1000-O6-P6-N6 -> 0.1 | R6: =COUNTIF('5.Simulation-fixed values'!$AQ$5:$AQ$1004, "<210000")/1000-O6-P6-Q6-N6 -> 0.889 | S6: =1-O6-P6-Q6-R6-N6 -> 0 | T6: =SUM(N6:S6) -> 1
B7: Max Online Reservations | C7: =_xlfn.MAXIFS('5.Simulation-fixed values'!$B$5:$B$1004, '5.Simulation-fixed values'!$J$5:$J$1004, "<0") -> 0 | D7: =_xlfn.MAXIFS('5.Simulation-fixed values'!$B$5:$B$1004, '5.Simulation-fixed values'!$J$5:$J$1004, ">=0", '5.Simulation-fixed values'!$J$5:$J$1004, "<150000") -> 0 | E7: =_xlfn.MAXIFS('5.Simulation-fixed values'!$B$5:$B$1004, '5.Simulation-fixed values'!$J$5:$J$1004, ">=150000", '5.Simulation-fixed values'!$J$5:$J$1004, "<155000") -> 683 | F7: =_xlfn.MAXIFS('5.Simulation-fixed values'!$B$5:$B$1004, '5.Simulation-fixed values'!$J$5:$J$1004, ">=155000", '5.Simulation-fixed values'!$J$5:$J$1004, "<158000") -> 699 | G7: =_xlfn.MAXIFS('5.Simulation-fixed values'!$B$5:$B$1004, '5.Simulation-fixed values'!$J$5:$J$1004, ">=158000", '5.Simulation-fixed values'!$J$5:$J$1004, "<162000") -> 693 | H7: =_xlfn.MAXIFS('5.Simulation-fixed values'!$B$5:$B$1004, '5.Simulation-fixed values'!$J$5:$J$1004, ">162000") -> 641 | M7: Max Online Reservations | N7: =_xlfn.MAXIFS('5.Simulation-fixed values'!$AI$5:$AI$1004, '5.Simulation-fixed values'!$AQ$5:$AQ$1004, "<0") -> 0 | O7: =_xlfn.MAXIFS('5.Simulation-fixed values'!$AI$5:$AI$1004, '5.Simulation-fixed values'!$AQ$5:$AQ$1004, ">=0", '5.Simulation-fixed values'!$AQ$5:$AQ$1004, "<180000") -> 387 | P7: =_xlfn.MAXIFS('5.Simulation-fixed values'!$AI$5:$AI$1004, '5.Simulation-fixed values'!$AQ$5:$AQ$1004, ">=180000", '5.Simulation-fixed values'!$AQ$5:$AQ$1004, "<190000") -> 424 | Q7: =_xlfn.MAXIFS('5.Simulation-fixed values'!$AI$5:$AI$1004, '5.Simulation-fixed values'!$AQ$5:$AQ$1004, ">=190000", '5.Simulation-fixed values'!$AQ$5:$AQ$1004, "<200000") -> 624 | R7: =_xlfn.MAXIFS('5.Simulation-fixed values'!$AI$5:$AI$1004, '5.Simulation-fixed values'!$AQ$5:$AQ$1004, ">=200000", '5.Simulation-fixed values'!$AQ$5:$AQ$1004, "<210000") -> 635 | S7: =_xlfn.MAXIFS('5.Simulation-fixed values'!$AI$5:$AI$1004, '5.Simulation-fixed values'!$AQ$5:$AQ$1004, ">210000") -> 0
B10: Compensation Risk Frequency when Room Price is $499 | M10: Compensation Risk Frequency when Room Price is $599
B12: Overbooked (rooms) | C12: No overbooked | D12: 1-3 | E12: 3-5 | F12: 5-7 | G12: 7-9 | H12: Over 10 | I12: Total | M12: Overbooked (rooms) | N12: No overbooked | O12: 1-3 | P12: 3-5 | Q12: 5-7 | R12: 7-9 | S12: Over 10 | T12: Total
B13: Probability | C13: =COUNTIF('5.Simulation-fixed values'!$G$5:$G$1004, "=00000")/1000 -> 0.979 | D13: =COUNTIF('5.Simulation-fixed values'!$G$5:$G$1004, "<4")/1000-C13 -> 0.015 | E13: =COUNTIF('5.Simulation-fixed values'!$G$5:$G$1004, "<6")/1000-D13-C13 -> 0.005 | F13: =COUNTIF('5.Simulation-fixed values'!$G$5:$G$1004, "<8")/1000-D13-E13-C13 -> 0.001 | G13: =COUNTIF('5.Simulation-fixed values'!$G$5:$G$1004, "<10")/1000-D13-E13-F13-C13 -> 0 | H13: =1-D13-E13-F13-G13-C13 -> 0 | I13: =SUM(C13:H13) -> 1 | M13: Probability | N13: =COUNTIF('5.Simulation-fixed values'!$AN$5:$AN$1004, "=00000")/1000 -> 0.93 | O13: =COUNTIF('5.Simulation-fixed values'!$AN$5:$AN$1004, "<4")/1000-N13 -> 0.044 | P13: =COUNTIF('5.Simulation-fixed values'!$AN$5:$AN$1004, "<6")/1000-O13-N13 -> 0.01 | Q13: =COUNTIF('5.Simulation-fixed values'!$AN$5:$AN$1004, "<8")/1000-O13-P13-N13 -> 0.007 | R13: =COUNTIF('5.Simulation-fixed values'!$AN$5:$AN$1004, "<10")/1000-O13-P13-Q13-N13 -> 0.004 | S13: =1-O13-P13-Q13-R13-N13 -> 0.005 | T13: =SUM(N13:S13) -> 1
B16: Vacant Room Risk Frequency when Room Price is $499 | M16: Vacant Room Risk Frequency when Room Price is $599
B18: Occupacy Rate | C18: <92% | D18: 92%-94% | E18: 94%-96% | F18: 96%-98% | G18: 98% - <100% | H18: 1 | I18: Total | M18: Occupacy Rate | N18: <92% | O18: 92%-94% | P18: 94%-96% | Q18: 96%-98% | R18: 98% - <100% | S18: 1 | T18: Total
B19: Probability | C19: =COUNTIF('5.Simulation-fixed values'!$M$5:$M$1004, "<0.92")/1000 -> 0.001 | D19: =COUNTIF('5.Simulation-fixed values'!$M$5:$M$1004, "<0.94")/1000-C19 -> 0.034 | E19: =COUNTIF('5.Simulation-fixed values'!$M$5:$M$1004, "<0.96")/1000-D19-C19 -> 0.223 | F19: =COUNTIF('5.Simulation-fixed values'!$M$5:$M$1004, "<0.98")/1000-D19-E19-C19 -> 0.453 | G19: =COUNTIF('5.Simulation-fixed values'!$M$5:$M$1004, "<1")/1000-D19-E19-F19-C19 -> 0.257 | H19: =1-D19-E19-F19-G19-C19 -> 0.032 | I19: =SUM(C19:H19) -> 1 | M19: Probability | N19: =COUNTIF('5.Simulation-fixed values'!$AT$5:$AT$1004, "<0.92")/1000 -> 0.011 | O19: =COUNTIF('5.Simulation-fixed values'!$AT$5:$AT$1004, "<0.94")/1000-N19 -> 0.019 | P19: =COUNTIF('5.Simulation-fixed values'!$AT$5:$AT$1004, "<0.96")/1000-O19-N19 -> 0.082 | Q19: =COUNTIF('5.Simulation-fixed values'!$AT$5:$AT$1004, "<0.98")/1000-O19-P19-N19 -> 0.36 | R19: =COUNTIF('5.Simulation-fixed values'!$AT$5:$AT$1004, "<1")/1000-O19-P19-Q19-N19 -> 0.431 | S19: =1-O19-P19-Q19-R19-N19 -> 0.097 | T19: =SUM(N19:S19) -> 1

Sheet 7. Output Summary
G1: DESCRIPTIVE STATISTICS (based on SIMULATED OUTPUT - constant values)
D3: Daily Profit ($'0000) when Room Price is $499 | S3: Daily Profit ($'0000) when Room Price is $599 | AJ3: Comparison
AH5: Daily Profit ($) when Room Price is | AO5: Occupancy Rate when Room Price is
AH7: 499 | AI7: 599 | AO7: 499 | AP7: 599
AG8: Minimum | AH8: =J31 -> 151388 | AI8: =Y31 -> 176014 | AN8: Minimum | AO8: =M30 -> 0.91555556 | AP8: =AB30 -> 0.85777778
AG9: Q1 | AH9: =QUARTILE('5.Simulation-fixed values'!J5:J1004,1) -> 157069 | AI9: =QUARTILE('5.Simulation-fixed values'!AQ5:AQ1004,1) -> 202164 | AN9: Q1 | AO9: =QUARTILE('5.Simulation-fixed values'!M5:M1004,1) -> 0.95777778 | AP9: =QUARTILE('5.Simulation-fixed values'!AT5:AT1004,1) -> 0.96888889
AG10: Q2 | AH10: =J24 -> 158564 | AI10: =Y24 -> 204159 | AN10: Q2 | AO10: =M23 -> 0.96888889 | AP10: =AB23 -> 0.98
AG11: Q3 | AH11: =QUARTILE('5.Simulation-fixed values'!J7:J1006,3) -> 160059 | AI11: =QUARTILE('5.Simulation-fixed values'!AQ7:AQ1006,3) -> 205755 | AN11: Q3 | AO11: =QUARTILE('5.Simulation-fixed values'!M5:M1004,3) -> 0.98 | AP11: =QUARTILE('5.Simulation-fixed values'!AT7:AT1006,3) -> 0.99111111
AG12: Maximum | AH12: =J32 -> 162750 | AI12: =Y32 -> 207750 | AN12: Maximum | AO12: =M31 -> 1 | AP12: =AB31 -> 1
AG13: IQR (middle 50%) | AH13: =AH11-AH9 -> 2990 | AI13: =AI11-AI9 -> 3591 | AN13: IQR (middle 50%) | AO13: =AO11-AO9 -> 0.022222222 | AP13: =AP11-AP9 -> 0.022222222
B19: Room Price is $499 | E19: Room Price is $499 | I19: Room Price is $499 | L19: Room Price is $499 | Q19: Room Price is $599 | T19: Room Price is $599 | X19: Room Price is $599 | AA19: Room Price is $599
B20: Bin | C20: Frequency | E20: Bins ($'0000) | F20: Frequency | G20: % Frequency | I20: Daily Profit | L20: Occupancy Rate | Q20: Bin | R20: Frequency | T20: Bins ($'0000) | U20: Frequency | V20: % Frequency | X20: Daily Profit | AA20: Occupancy Rate
B21: 150000 | C21: {=FREQUENCY('5.Simulation-fixed values'!J5:J1004,'7. Output Summary'!B21:B34)} -> 0 | E21: =B21/10000 -> 15 | F21: =C21 -> 0 | G21: =F21/1000 -> 0 | L21: Mean | M21: 0.96949111 | Q21: 180000 | R21: {=FREQUENCY('5.Simulation-fixed values'!AQ5:AQ1004,'7. Output Summary'!Q21:Q40)} -> 2 | T21: =Q21/10000 -> 18 | U21: =R21 -> 2 | V21: =U21/1000 -> 0.002 | AA21: Mean | AB21: 0.97748667
B22: 152000 | C22: 1 | E22: =B22/10000 -> 15.2 | F22: =C22 -> 1 | G22: =F22/1000 -> 0.001 | I22: Mean | J22: 158615.68 | L22: Standard Error | M22: 0.00050390562 | Q22: =Q21+2000 -> 182000 | R22: 1 | T22: =Q22/10000 -> 18.2 | U22: =R22 -> 1 | V22: =U22/1000 -> 0.001 | X22: Mean | Y22: 203403.4 | AA22: Standard Error | AB22: 0.00056360464
B23: 154000 | C23: 19 | E23: =B23/10000 -> 15.4 | F23: =C23 -> 19 | G23: =F23/1000 -> 0.019 | I23: Standard Error | J23: 66.42785 | L23: Median | M23: 0.96888889 | Q23: =Q22+2000 -> 184000 | R23: 1 | T23: =Q23/10000 -> 18.4 | U23: =R23 -> 1 | V23: =U23/1000 -> 0.001 | X23: Standard Error | Y23: 109.95254 | AA23: Median | AB23: 0.98
B24: =B23+2000 -> 156000 | C24: 99 | E24: =B24/10000 -> 15.6 | F24: =C24 -> 99 | G24: =F24/1000 -> 0.099 | I24: Median | J24: 158564 | L24: Mode | M24: 0.96888889 | Q24: =Q23+2000 -> 186000 | R24: 1 | T24: =Q24/10000 -> 18.6 | U24: =R24 -> 1 | V24: =U24/1000 -> 0.001 | X24: Median | Y24: 204159 | AA24: Mode | AB24: 1
B25: =B24+2000 -> 158000 | C25: 276 | E25: =B25/10000 -> 15.8 | F25: =C25 -> 276 | G25: =F25/1000 -> 0.276 | I25: Mode | J25: 158564 | L25: Standard Deviation | M25: 0.015934895 | Q25: =Q24+2000 -> 188000 | R25: 3 | T25: =Q25/10000 -> 18.8 | U25: =R25 -> 3 | V25: =U25/1000 -> 0.003 | X25: Mode | Y25: 204558 | AA25: Standard Deviation | AB25: 0.017822744
B26: =B25+2000 -> 160000 | C26: 318 | E26: =B26/10000 -> 16 | F26: =C26 -> 318 | G26: =F26/1000 -> 0.318 | I26: Standard Deviation | J26: 2100.6331 | L26: Sample Variance | M26: 0.00025392088 | Q26: =Q25+2000 -> 190000 | R26: 3 | T26: =Q26/10000 -> 19 | U26: =R26 -> 3 | V26: =U26/1000 -> 0.003 | X26: Standard Deviation | Y26: 3477.0046 | AA26: Sample Variance | AB26: 0.00031765019
B27: =B26+2000 -> 162000 | C27: 235 | E27: =B27/10000 -> 16.2 | F27: =C27 -> 235 | G27: =F27/1000 -> 0.235 | I27: Sample Variance | J27: 4412659.3 | L27: Kurtosis | M27: -0.33002381 | Q27: =Q26+2000 -> 192000 | R27: 4 | T27: =Q27/10000 -> 19.2 | U27: =R27 -> 4 | V27: =U27/1000 -> 0.004 | X27: Sample Variance | Y27: 12089561 | AA27: Kurtosis | AB27: 5.3951155
B28: =B27+2000 -> 164000 | C28: 52 | E28: =B28/10000 -> 16.4 | F28: =C28 -> 52 | G28: =F28/1000 -> 0.052 | I28: Kurtosis | J28: -0.33532907 | L28: Skewness | M28: -0.18677864 | Q28: =Q27+2000 -> 194000 | R28: 10 | T28: =Q28/10000 -> 19.4 | U28: =R28 -> 10 | V28: =U28/1000 -> 0.01 | X28: Kurtosis | Y28: 11.768304 | AA28: Skewness | AB28: -1.5957878
B29: =B28+2000 -> 166000 | C29: 0 | E29: =B29/10000 -> 16.6 | F29: =C29 -> 0 | G29: =F29/1000 -> 0 | I29: Skewness | J29: -0.25554145 | L29: Range | M29: 0.084444444 | Q29: =Q28+2000 -> 196000 | R29: 6 | T29: =Q29/10000 -> 19.6 | U29: =R29 -> 6 | V29: =U29/1000 -> 0.006 | X29: Skewness | Y29: -2.5158741 | AA29: Range | AB29: 0.14222222
B30: =B29+2000 -> 168000 | C30: 0 | I30: Range | J30: 11362 | L30: Minimum | M30: 0.91555556 | Q30: =Q29+2000 -> 198000 | R30: 18 | T30: =Q30/10000 -> 19.8 | U30: =R30 -> 18 | V30: =U30/1000 -> 0.018 | X30: Range | Y30: 31736 | AA30: Minimum | AB30: 0.85777778
B31: =B30+2000 -> 170000 | C31: 0 | I31: Minimum | J31: 151388 | L31: Maximum | M31: 1 | Q31: =Q30+2000 -> 200000 | R31: 62 | T31: =Q31/10000 -> 20 | U31: =R31 -> 62 | V31: =U31/1000 -> 0.062 | X31: Minimum | Y31: 176014 | AA31: Maximum | AB31: 1
B32: =B31+2000 -> 172000 | C32: 0 | I32: Maximum | J32: 162750 | L32: Sum | M32: 969.49111 | Q32: =Q31+2000 -> 202000 | R32: 136 | T32: =Q32/10000 -> 20.2 | U32: =R32 -> 136 | V32: =U32/1000 -> 0.136 | X32: Maximum | Y32: 207750 | AA32: Sum | AB32: 977.48667
B33: =B32+2000 -> 174000 | C33: 0 | I33: Sum | J33: 158615678 | L33: Count | M33: 1000 | Q33: =Q32+2000 -> 204000 | R33: 244 | T33: =Q33/10000 -> 20.4 | U33: =R33 -> 244 | V33: =U33/1000 -> 0.244 | X33: Sum | Y33: 203403396 | AA33: Count | AB33: 1000
B34: =B33+2000 -> 176000 | C34: 0 | I34: Count | J34: 1000 | Q34: =Q33+2000 -> 206000 | R34: 296 | T34: =Q34/10000 -> 20.6 | U34: =R34 -> 296 | V34: =U34/1000 -> 0.296 | X34: Count | Y34: 1000
C35: 0 | Q35: =Q34+2000 -> 208000 | R35: 213 | T35: =Q35/10000 -> 20.8 | U35: =R35 -> 213 | V35: =U35/1000 -> 0.213
Q36: =Q35+2000 -> 210000 | R36: 0 | T36: =Q36/10000 -> 21 | U36: =R36 -> 0 | V36: =U36/1000 -> 0
Q37: =Q36+2000 -> 212000 | R37: 0 | T37: =Q37/10000 -> 21.2 | U37: =R37 -> 0 | V37: =U37/1000 -> 0
Q38: =Q37+2000 -> 214000 | R38: 0 | T38: =Q38/10000 -> 21.4 | U38: =R38 -> 0 | V38: =U38/1000 -> 0
Q39: =Q38+2000 -> 216000 | R39: 0 | T39: =Q39/10000 -> 21.6 | U39: =R39 -> 0 | V39: =U39/1000 -> 0
Q40: =Q39+2000 -> 218000 | R40: 0 | T40: =Q40/10000 -> 21.8 | U40: =R40 -> 0 | V40: =U40/1000 -> 0
R41: 0
I43: Room Price is $499 | X43: Room Price is $599
I44: Soldout Status | J44: Frequency | K44: %Frequency | X44: Soldout Status | Y44: Frequency | Z44: %Frequency
I45: Yes | J45: =COUNTIF('5.Simulation-fixed values'!K5:$K$1004,'7. Output Summary'!I45) -> 32 | K45: =J45/1000 -> 0.032 | X45: Yes | Y45: =COUNTIF('5.Simulation-fixed values'!$AR$5:$AR$1004,'7. Output Summary'!X45) -> 97 | Z45: =Y45/1000 -> 0.097
I46: No | J46: =COUNTIF('5.Simulation-fixed values'!K5:$K$1004,'7. Output Summary'!I46) -> 968 | K46: =J46/1000 -> 0.968 | X46: No | Y46: =COUNTIF('5.Simulation-fixed values'!$AR$5:$AR$1004,'7. Output Summary'!X46) -> 903 | Z46: =Y46/1000 -> 0.903
I47: Total | J47: =SUM(J45:J46) -> 1000 | K47: =J47/1000 -> 1 | X47: Total | Y47: =SUM(Y45:Y46) -> 1000 | Z47: =Y47/1000 -> 1
I57: Room Price is $499 | X57: Room Price is $599
I58: Overbooked Status | J58: Frequency | K58: %Frequency | X58: Overbooked Status | Y58: Frequency | Z58: %Frequency
...
